<?xml version="1.0"?>
<robot xmlns:xacro="http://www.ros.org/wiki/xacro">
  <macro name="cylinder_inertial" params="name m r h">
    <inertial name="${name}_intertial">
      <mass value="${m}"/>
      <inertia  ixx="${m*(3*r*r+h*h)/12}" ixy = "0" ixz = "0"
        iyy="${m*(3*r*r+h*h)/12}" iyz = "0"
        izz="${m*r*r/2}"/>
    </inertial>
  </macro>

  <macro name="box_inertial" params="name m x y z">
    <inertial name="${name}_inertial">
      <mass value="${m}"/>
      <inertia  ixx="${m*(y*y+z*z)/12}" ixy = "0" ixz = "0"
        iyy="${m*(x*x+y*y)/12}" iyz = "0"
        izz="${m*(x*x+z*z)/12}"/>
    </inertial>
  </macro>

  <macro name="sphere_inertial" params="name m r">
    <inertial name="${name}_inertial">
      <mass value="${m}"/>
      <inertia  ixx="${2*m*r*r/5}" ixy = "0" ixz = "0"
        iyy="${2*m*r*r/5}" iyz = "0"
        izz="${2*m*r*r/5}"/>
    </inertial>
  </macro>

  <macro name="wheel" params="id m r w x y z">

    <joint name="wheel_joint_${id}" type="continuous">
      <axis xyz="0 1 0" />
      <origin xyz="${x} ${y} ${z}" rpy="0 0 0"/>
      <parent link="chassis"/>
      <child link="wheel_${id}"/>
    </joint>

    <link name='wheel_${id}'>

      <xacro:cylinder_inertial name="wheel_${id}_inertial" m="${m}" r="${r}" h="${w}"/>

      <collision name='wheel_${id}_collision'>
        <geometry>
          <cylinder radius="${r}" length="${w}"/>
        </geometry>
      </collision>

      <visual name='wheel_${id}_visual'>
        <origin xyz="0 0 0" rpy="${pi / 2} 0 0"/>
        <geometry>
          <cylinder radius="${r}" length="${w}"/>
        </geometry>
      </visual>

    </link>

  </macro>

</robot>